# 毕设

## 2020/11/11

1. 项目 settting-project structure 中将code、t-e文件夹设置为source源，解决互相调用的问题

2. ```python
   python-coveralls 2.9.3
   scipy 1.5.4
   scikit-learn 0.23.2
   scikit-image 0.17.2
   dlib 19.21.0
   opencv-python 4.4.0.46
   sk-video 1.1.10
   tables 3.6.1
   cmake 3.18.2
   numpy 1.19.4
   soundfile 0.10.3.post1
   
   卸载tensorflow 2.2.0 安装 1.13.1
   pip安装失败！pip install tensorflow==1.13.1 -i https://pypi.tuna.tsinghua.edu.cn/simple
   直接在setting里安装成功
   ```

3. 笔记 https://zhuanlan.zhihu.com/p/48670591
   linux运行示例 https://asciinema.org/a/kXIDzZt1UzRioL1gDPzOy9VkZ no windows

4. window在文件夹下git bash运行 ./run.sh

   Loading from: C:/Users/37161/results/
   Traceback (most recent call last):
     File "./code/training_evaluation/test.py", line 573, in <module>
       tf.app.run()
     File "C:\Users\37161\AppData\Local\Programs\Python\Python37\lib\site-packages\tensorflow\python\platform\app.py", line 125, in run
       _sys.exit(main(argv))
     File "./code/training_evaluation/test.py", line 514, in main
       saver.restore(sess, latest_checkpoint)
     File "C:\Users\37161\AppData\Local\Programs\Python\Python37\lib\site-packages\tensorflow\python\training\saver.py", line 1264, in restore
       raise ValueError("Can't load save_path when it is None.")
   ValueError: Can't load save_path when it is None.
   **ln: failed to create symbolic link 'dlib': File exists**
   **mkdir: cannot create directory ‘results’: File exists**
   Traceback (most recent call last):
     File "./code/lip_tracking/VisualizeLip.py", line 36, in <module>
       predictor = dlib.shape_predictor(predictor_path)
   **RuntimeError: Unable to open dlib/shape_predictor_68_face_landmarks.dat**
   ./run.sh: line 46: ffmpeg: command not found

5.  运行VisualizeLip.py

   ```
   python code/lip_tracking/VisualizeLip.py -i data/sample_video.mp4 -o data/sample_video.mp4
   ```

   - **RuntimeError: Unable to open dlib/shape_predictor_68_face_landmarks.dat**

     -->pyinstaller打包教程 pip install pyinstaller

     ```
  Successfully installed altgraph-0.17 future-0.18.2 pefile-2019.4.18 pyinstaller-4.0 pyinstaller-hooks-contrib-2020.10 pywin32-ctypes-0.2.0
     ```

      **(don't work)**
   
     发现是路径问题，更改路径后解决
   
   - ```
     Traceback (most recent call last):
       File "code/lip_tracking/VisualizeLip.py", line 45, in <module>
         outputdict=outputparameters)
    File "C:\Users\37161\AppData\Local\Programs\Python\Python37\lib\site-packages\skvideo\io\ffmpeg.py", line 72, in __init__
         assert _HAS_FFMPEG, "Cannot find installation of real FFmpeg (which comes with ffprobe)."
  AssertionError: **Cannot find installation of real FFmpeg** (which comes with ffprobe).
     ```

     https://blog.csdn.net/qq_29931083/article/details/105443628

     没有卸载sk-video直接安装了scikit-video 1.1.11

     ffmpeg下载地址 https://github.com/BtbN/FFmpeg-Builds/releases
   
     我下载了 ffmpeg-n4.3.1-25-g1936413eda-win64-lgpl-4.3（迅雷win64）解压加入系统path（\bin**\\**）
   
   - ```
     Traceback (most recent call last):
       File "C:\Users\37161\AppData\Local\Programs\Python\Python37\lib\site-packages\skvideo\io\ffmpeg.py", line 271, in _read_frame_data
         assert len(arr) == framesize
     AssertionError
     
     During handling of the above exception, another exception occurred:
     
     Traceback (most recent call last):
       File "code/lip_tracking/VisualizeLip.py", line 95, in <module>
         for frame in reader.nextFrame():
       File "C:\Users\37161\AppData\Local\Programs\Python\Python37\lib\site-packages\skvideo\io\ffmpeg.py", line 297, in nextFrame
         yield self._readFrame()
       File "C:\Users\37161\AppData\Local\Programs\Python\Python37\lib\site-packages\skvideo\io\ffmpeg.py", line 281, in _readFrame
         s = self._read_frame_data()
    File "C:\Users\37161\AppData\Local\Programs\Python\Python37\lib\site-packages\skvideo\io\ffmpeg.py", line 275, in _read_frame_data
         raise RuntimeError("%s" % (err1,))
  RuntimeError
     ```
   
     再次运行又没有错误了，成功提取了唇部轮廓，但他说检测不到
   
     

## 2020/11/12

1. 尝试将video识别口型后记录在新建video文件中，昨天虽然显示报错，但是嘴型识别已经完成了，再次运行是在已经识别的基础上，并显示识别不到。

   ```git bash
   python code/lip_tracking/VisualizeLip.py -i data/sample_video.mp4 -o data/video.mp4
   ```

   -->当输出为自己新创建的.mp4文件时，错误不会出现，应该是读写同一个video会有帧长问题的出现。现在已经解决了VisualizeLip.py文件的问题。

2. 执行 ./run.sh

   ```
   [image2 @ 00000221a4a48840] Could find no file with path './results/mouth/frame_%*.png' and index in the range 0-4
   ./results/mouth/frame_%*.png: No such file or directory
   ```

   results中出现了output_video.mp4与前面的结果相同

   ```
   Loading from: C:/Users/37161/results/
   Traceback (most recent call last):
     File "./code/training_evaluation/test.py", line 573, in <module>
       tf.app.run()
     File "C:\Users\37161\AppData\Local\Programs\Python\Python37\lib\site-packages\tensorflow\python\platform\app.py", line 125, in run
       _sys.exit(main(argv))
     File "./code/training_evaluation/test.py", line 514, in main
       saver.restore(sess, latest_checkpoint)
     File "C:\Users\37161\AppData\Local\Programs\Python\Python37\lib\site-packages\tensorflow\python\training\saver.py", line 1264, in restore
       raise ValueError("Can't load save_path when it is None.")
   ValueError: Can't load save_path when it is None.
   ln: failed to create symbolic link 'dlib': File exists
   ./run.sh: line 42: mkdirs: command not found
   ```

   